File: 2a8b805a-7d2b-49d1-9c5d-bf6319119fb7.json
Error: Update application failed
Timestamp: 2025-08-13T15:28:58.628050
Stack trace:
Traceback (most recent call last):
  File "/home/runner/work/gcommon/gcommon/doc_update_manager.py", line 447, in _process_single_file_safely
    self.process_update_file_data(update_file, update_data)
  File "/home/runner/work/gcommon/gcommon/doc_update_manager.py", line 495, in process_update_file_data
    raise Exception("Update application failed")
Exception: Update application failed
