File: 81cb2cf4-92f3-40c2-82f9-f82e4ec5e6af.json
Error: Update application failed
Timestamp: 2025-07-21T23:47:51.849418
Stack trace:
Traceback (most recent call last):
  File "/home/runner/work/gcommon/gcommon/doc_update_manager.py", line 447, in _process_single_file_safely
    self.process_update_file_data(update_file, update_data)
  File "/home/runner/work/gcommon/gcommon/doc_update_manager.py", line 495, in process_update_file_data
    raise Exception("Update application failed")
Exception: Update application failed
