File: 830b9f10-3def-4b8f-a90e-4d7b6ff6b394.json
Error: Update application failed
Timestamp: 2025-08-12T17:34:49.416177
Stack trace:
Traceback (most recent call last):
  File "/home/runner/work/gcommon/gcommon/doc_update_manager.py", line 447, in _process_single_file_safely
    self.process_update_file_data(update_file, update_data)
  File "/home/runner/work/gcommon/gcommon/doc_update_manager.py", line 495, in process_update_file_data
    raise Exception("Update application failed")
Exception: Update application failed
