File: 6095eecb-57f9-4d41-a7a0-28e1951bd8c9.json
Error: Update application failed
Timestamp: 2025-07-27T02:50:53.309233
Stack trace:
Traceback (most recent call last):
  File "/home/runner/work/gcommon/gcommon/doc_update_manager.py", line 447, in _process_single_file_safely
    self.process_update_file_data(update_file, update_data)
  File "/home/runner/work/gcommon/gcommon/doc_update_manager.py", line 495, in process_update_file_data
    raise Exception("Update application failed")
Exception: Update application failed
