File: 42dd4ac3-2936-4eff-9340-b87491da1af0.json
Error: Update application failed
Timestamp: 2025-08-12T17:34:49.350725
Stack trace:
Traceback (most recent call last):
  File "/home/runner/work/gcommon/gcommon/doc_update_manager.py", line 447, in _process_single_file_safely
    self.process_update_file_data(update_file, update_data)
  File "/home/runner/work/gcommon/gcommon/doc_update_manager.py", line 495, in process_update_file_data
    raise Exception("Update application failed")
Exception: Update application failed
