File: d69c1873-9531-4bb3-a9ce-5a8e0ca3d485.json
Error: Update application failed
Timestamp: 2025-08-13T15:28:58.809242
Stack trace:
Traceback (most recent call last):
  File "/home/runner/work/gcommon/gcommon/doc_update_manager.py", line 447, in _process_single_file_safely
    self.process_update_file_data(update_file, update_data)
  File "/home/runner/work/gcommon/gcommon/doc_update_manager.py", line 495, in process_update_file_data
    raise Exception("Update application failed")
Exception: Update application failed
