File: cf25700a-c681-497d-993e-02aa03239a47.json
Error: Update application failed
Timestamp: 2025-07-21T02:59:36.255150
Stack trace:
Traceback (most recent call last):
  File "/home/runner/work/gcommon/gcommon/doc_update_manager.py", line 447, in _process_single_file_safely
    self.process_update_file_data(update_file, update_data)
  File "/home/runner/work/gcommon/gcommon/doc_update_manager.py", line 495, in process_update_file_data
    raise Exception("Update application failed")
Exception: Update application failed
