File: 8c4bd2d1-7e71-4f75-9cac-9d4c31dcbf6e.json
Error: Update application failed
Timestamp: 2025-07-21T23:53:43.575493
Stack trace:
Traceback (most recent call last):
  File "/home/runner/work/gcommon/gcommon/doc_update_manager.py", line 447, in _process_single_file_safely
    self.process_update_file_data(update_file, update_data)
  File "/home/runner/work/gcommon/gcommon/doc_update_manager.py", line 495, in process_update_file_data
    raise Exception("Update application failed")
Exception: Update application failed
