File: 11e2a7a4-356b-4749-b6bc-cce558f244bf.json
Error: Update application failed
Timestamp: 2025-07-23T03:39:22.269782
Stack trace:
Traceback (most recent call last):
  File "/workspace/gcommon/doc_update_manager.py", line 447, in _process_single_file_safely
    self.process_update_file_data(update_file, update_data)
  File "/workspace/gcommon/doc_update_manager.py", line 495, in process_update_file_data
    raise Exception("Update application failed")
Exception: Update application failed
